<?xml version='1.0'?>
<sdf version='1.6'>
  <model name='panda'>
    <link name='panda_link0'>
      <pose frame=''>0 0 0 0 -0 0</pose>
      <inertial>
        <pose frame=''>-0.025566 -2.9e-05 0.057332 0 -0 0</pose>
        <mass>2.92</mass>
        <inertia>
          <ixx>0.00782229</ixx>
          <ixy>-1.56192e-05</ixy>
          <ixz>-0.00126006</ixz>
          <iyy>0.0109028</iyy>
          <iyz>1.08234e-05</iyz>
          <izz>0.0102356</izz>
        </inertia>
      </inertial>
      <gravity>1</gravity>
      <velocity_decay/>
      <self_collide>0</self_collide>
      <enable_wind>0</enable_wind>
      <kinematic>0</kinematic>
      <visual name='panda_link0_visual'>
        <pose frame=''>0 0 0 0 -0 0</pose>
        <geometry>
          <mesh>
            <scale>1 1 1</scale>
            <uri>/home/medad/RoboticsProject/catkin_ws/src/franka_gazebo/meshes/visual/link0.dae</uri>
          </mesh>
        </geometry>
        <transparency>0</transparency>
        <cast_shadows>1</cast_shadows>
      </visual>
      <collision name='panda_link0_collision'>
        <laser_retro>0</laser_retro>
        <max_contacts>10</max_contacts>
        <pose frame=''>0 0 0 0 -0 0</pose>
        <geometry>
          <mesh>
            <uri>/home/medad/RoboticsProject/catkin_ws/src/franka_gazebo/meshes/collision/link0.stl</uri>
            <scale>1 1 1</scale>
          </mesh>
        </geometry>
        <surface>
          <friction>
            <ode>
              <mu>1</mu>
              <mu2>1</mu2>
              <fdir1>0 0 0</fdir1>
              <slip1>0</slip1>
              <slip2>0</slip2>
            </ode>
            <torsional>
              <coefficient>1</coefficient>
              <patch_radius>0</patch_radius>
              <surface_radius>0</surface_radius>
              <use_patch_radius>1</use_patch_radius>
              <ode>
                <slip>0</slip>
              </ode>
            </torsional>
          </friction>
          <bounce>
            <restitution_coefficient>0</restitution_coefficient>
            <threshold>1e+06</threshold>
          </bounce>
          <contact>
            <collide_without_contact>0</collide_without_contact>
            <collide_without_contact_bitmask>1</collide_without_contact_bitmask>
            <collide_bitmask>1</collide_bitmask>
            <ode>
              <soft_cfm>0</soft_cfm>
              <soft_erp>0.2</soft_erp>
              <kp>1e+13</kp>
              <kd>1</kd>
              <max_vel>0.01</max_vel>
              <min_depth>0</min_depth>
            </ode>
            <bullet>
              <split_impulse>1</split_impulse>
              <split_impulse_penetration_threshold>-0.01</split_impulse_penetration_threshold>
              <soft_cfm>0</soft_cfm>
              <soft_erp>0.2</soft_erp>
              <kp>1e+13</kp>
              <kd>1</kd>
            </bullet>
          </contact>
        </surface>
      </collision>
    </link>
    <link name='panda_leftfinger'>
      <pose frame=''>0.088 -0 0.8676 3.14159 -0 0.785398</pose>
      <inertial>
        <pose frame=''>0 0.014564 0.022794 0 -0 0</pose>
        <mass>0.1</mass>
        <inertia>
          <ixx>3.01221e-05</ixx>
          <ixy>0</ixy>
          <ixz>0</ixz>
          <iyy>2.95874e-05</iyy>
          <iyz>0</iyz>
          <izz>6.95125e-06</izz>
        </inertia>
      </inertial>
      <velocity_decay/>
      <gravity>1</gravity>
      <velocity_decay/>
      <self_collide>0</self_collide>
      <enable_wind>0</enable_wind>
      <kinematic>0</kinematic>
      <visual name='panda_leftfinger_visual'>
        <pose frame=''>0 0 0 0 -0 0</pose>
        <geometry>
          <mesh>
            <scale>1 1 1</scale>
            <uri>/home/medad/RoboticsProject/catkin_ws/src/franka_gazebo/meshes/visual/finger.dae</uri>
          </mesh>
        </geometry>
        <material>
          <script>
            <uri>__default__</uri>
            <name>__default__</name>
          </script>
        </material>
        <transparency>0</transparency>
        <cast_shadows>1</cast_shadows>
      </visual>
      <collision name='panda_leftfinger_collision'>
        <laser_retro>0</laser_retro>
        <max_contacts>10</max_contacts>
        <pose frame=''>0 0 0 0 -0 0</pose>
        <geometry>
          <mesh>
            <uri>/home/medad/RoboticsProject/catkin_ws/src/franka_gazebo/meshes/collision/finger.stl</uri>
            <scale>1 1 1</scale>
          </mesh>
        </geometry>
        <surface>
          <friction>
            <ode>
              <mu>100</mu>
              <mu2>100</mu2>
              <fdir1>0 0 1</fdir1>
              <slip1>0</slip1>
              <slip2>0</slip2>
            </ode>
            <torsional>
              <coefficient>100</coefficient>
              <patch_radius>0.1</patch_radius>
              <surface_radius>0.1</surface_radius>
              <use_patch_radius>1</use_patch_radius>
              <ode>
                <slip>0</slip>
              </ode>
            </torsional>
          </friction>
          <bounce>
            <restitution_coefficient>0</restitution_coefficient>
            <threshold>1e+06</threshold>
          </bounce>
          <contact>
            <collide_without_contact>0</collide_without_contact>
            <collide_without_contact_bitmask>1</collide_without_contact_bitmask>
            <collide_bitmask>1</collide_bitmask>
            <ode>
              <soft_cfm>0</soft_cfm>
              <soft_erp>0.2</soft_erp>
              <kp>100000</kp>
              <kd>1</kd>
              <max_vel>0.01</max_vel>
              <min_depth>0</min_depth>
            </ode>
            <bullet>
              <split_impulse>1</split_impulse>
              <split_impulse_penetration_threshold>-0.01</split_impulse_penetration_threshold>
              <soft_cfm>0</soft_cfm>
              <soft_erp>0.2</soft_erp>
              <kp>100000</kp>
              <kd>1</kd>
            </bullet>
          </contact>
        </surface>
      </collision>
    </link>
    <link name='panda_link1'>
      <pose frame=''>0 -0 0.333 0 -0 0</pose>
      <inertial>
        <pose frame=''>0 -0.032496 -0.067582 0 -0 0</pose>
        <mass>2.74</mass>
        <inertia>
          <ixx>0.0180417</ixx>
          <ixy>0</ixy>
          <ixz>0</ixz>
          <iyy>0.0159136</iyy>
          <iyz>0.00467584</iyz>
          <izz>0.00620691</izz>
        </inertia>
      </inertial>
      <gravity>1</gravity>
      <velocity_decay/>
      <self_collide>0</self_collide>
      <enable_wind>0</enable_wind>
      <kinematic>0</kinematic>
      <visual name='panda_link1_visual'>
        <pose frame=''>0 0 0 0 -0 0</pose>
        <geometry>
          <mesh>
            <scale>1 1 1</scale>
            <uri>/home/medad/RoboticsProject/catkin_ws/src/franka_gazebo/meshes/visual/link1.dae</uri>
          </mesh>
        </geometry>
        <transparency>1</transparency>
        <cast_shadows>1</cast_shadows>
        <material>
          <shader type='vertex'>
            <normal_map>__default__</normal_map>
          </shader>
          <script>
            <name>ModelPreview_1::panda_link1::panda_link1_visual_MATERIAL_</name>
          </script>
          <ambient>0 0 0 1</ambient>
          <diffuse>0 0 0 1</diffuse>
          <specular>0 0 0 1</specular>
          <emissive>0 0 0 1</emissive>
        </material>
      </visual>
      <collision name='panda_link1_collision'>
        <laser_retro>0</laser_retro>
        <max_contacts>10</max_contacts>
        <pose frame=''>0 0 0 0 -0 0</pose>
        <geometry>
          <mesh>
            <uri>/home/medad/RoboticsProject/catkin_ws/src/franka_gazebo/meshes/collision/link1.stl</uri>
            <scale>1 1 1</scale>
          </mesh>
        </geometry>
        <surface>
          <friction>
            <ode>
              <mu>1</mu>
              <mu2>1</mu2>
              <fdir1>0 0 0</fdir1>
              <slip1>0</slip1>
              <slip2>0</slip2>
            </ode>
            <torsional>
              <coefficient>1</coefficient>
              <patch_radius>0</patch_radius>
              <surface_radius>0</surface_radius>
              <use_patch_radius>1</use_patch_radius>
              <ode>
                <slip>0</slip>
              </ode>
            </torsional>
          </friction>
          <bounce>
            <restitution_coefficient>0</restitution_coefficient>
            <threshold>1e+06</threshold>
          </bounce>
          <contact>
            <collide_without_contact>0</collide_without_contact>
            <collide_without_contact_bitmask>1</collide_without_contact_bitmask>
            <collide_bitmask>1</collide_bitmask>
            <ode>
              <soft_cfm>0</soft_cfm>
              <soft_erp>0.2</soft_erp>
              <kp>1e+13</kp>
              <kd>1</kd>
              <max_vel>0.01</max_vel>
              <min_depth>0</min_depth>
            </ode>
            <bullet>
              <split_impulse>1</split_impulse>
              <split_impulse_penetration_threshold>-0.01</split_impulse_penetration_threshold>
              <soft_cfm>0</soft_cfm>
              <soft_erp>0.2</soft_erp>
              <kp>1e+13</kp>
              <kd>1</kd>
            </bullet>
          </contact>
        </surface>
      </collision>
    </link>
    <link name='panda_link2'>
      <pose frame=''>0 -0 0.333 -1.5708 -0 0</pose>
      <inertial>
        <pose frame=''>0 -0.06861 0.032229 0 -0 0</pose>
        <mass>2.74</mass>
        <inertia>
          <ixx>0.0182856</ixx>
          <ixy>0</ixy>
          <ixz>0</ixz>
          <iyy>0.00621358</iyy>
          <iyz>0</iyz>
          <izz>0.0161514</izz>
        </inertia>
      </inertial>
      <gravity>1</gravity>
      <velocity_decay/>
      <self_collide>0</self_collide>
      <enable_wind>0</enable_wind>
      <kinematic>0</kinematic>
      <visual name='panda_link2_visual'>
        <pose frame=''>0 0 0 0 -0 0</pose>
        <geometry>
          <mesh>
            <scale>1 1 1</scale>
            <uri>/home/medad/RoboticsProject/catkin_ws/src/franka_gazebo/meshes/visual/link2.dae</uri>
          </mesh>
        </geometry>
        <transparency>1</transparency>
        <cast_shadows>1</cast_shadows>
        <material>
          <shader type='vertex'>
            <normal_map>__default__</normal_map>
          </shader>
          <script>
            <name>ModelPreview_1::panda_link2::panda_link2_visual_MATERIAL_</name>
          </script>
          <ambient>0 0 0 1</ambient>
          <diffuse>0 0 0 1</diffuse>
          <specular>0 0 0 1</specular>
          <emissive>0 0 0 1</emissive>
        </material>
      </visual>
      <collision name='panda_link2_collision'>
        <laser_retro>0</laser_retro>
        <max_contacts>10</max_contacts>
        <pose frame=''>0 0 0 0 -0 0</pose>
        <geometry>
          <mesh>
            <uri>/home/medad/RoboticsProject/catkin_ws/src/franka_gazebo/meshes/collision/link2.stl</uri>
            <scale>1 1 1</scale>
          </mesh>
        </geometry>
        <surface>
          <friction>
            <ode>
              <mu>1</mu>
              <mu2>1</mu2>
              <fdir1>0 0 0</fdir1>
              <slip1>0</slip1>
              <slip2>0</slip2>
            </ode>
            <torsional>
              <coefficient>1</coefficient>
              <patch_radius>0</patch_radius>
              <surface_radius>0</surface_radius>
              <use_patch_radius>1</use_patch_radius>
              <ode>
                <slip>0</slip>
              </ode>
            </torsional>
          </friction>
          <bounce>
            <restitution_coefficient>0</restitution_coefficient>
            <threshold>1e+06</threshold>
          </bounce>
          <contact>
            <collide_without_contact>0</collide_without_contact>
            <collide_without_contact_bitmask>1</collide_without_contact_bitmask>
            <collide_bitmask>1</collide_bitmask>
            <ode>
              <soft_cfm>0</soft_cfm>
              <soft_erp>0.2</soft_erp>
              <kp>1e+13</kp>
              <kd>1</kd>
              <max_vel>0.01</max_vel>
              <min_depth>0</min_depth>
            </ode>
            <bullet>
              <split_impulse>1</split_impulse>
              <split_impulse_penetration_threshold>-0.01</split_impulse_penetration_threshold>
              <soft_cfm>0</soft_cfm>
              <soft_erp>0.2</soft_erp>
              <kp>1e+13</kp>
              <kd>1</kd>
            </bullet>
          </contact>
        </surface>
      </collision>
    </link>
    <link name='panda_link3'>
      <pose frame=''>-0 -0 0.649 0 -0 0</pose>
      <inertial>
        <pose frame=''>0.046989 0.031637 -0.031704 0 -0 0</pose>
        <mass>2.38</mass>
        <inertia>
          <ixx>0.00771377</ixx>
          <ixy>-0.00248491</ixy>
          <ixz>-0.00332148</ixz>
          <iyy>0.00989108</iyy>
          <iyz>-0.00217796</iyz>
          <izz>0.00811724</izz>
        </inertia>
      </inertial>
      <gravity>1</gravity>
      <velocity_decay/>
      <self_collide>0</self_collide>
      <enable_wind>0</enable_wind>
      <kinematic>0</kinematic>
      <visual name='panda_link3_visual'>
        <pose frame=''>0 0 0 0 -0 0</pose>
        <geometry>
          <mesh>
            <scale>1 1 1</scale>
            <uri>/home/medad/RoboticsProject/catkin_ws/src/franka_gazebo/meshes/visual/link3.dae</uri>
          </mesh>
        </geometry>
        <transparency>0</transparency>
        <cast_shadows>1</cast_shadows>
      </visual>
      <collision name='panda_link3_collision'>
        <laser_retro>0</laser_retro>
        <max_contacts>10</max_contacts>
        <pose frame=''>0 0 0 0 -0 0</pose>
        <geometry>
          <mesh>
            <uri>/home/medad/RoboticsProject/catkin_ws/src/franka_gazebo/meshes/collision/link3.stl</uri>
            <scale>1 1 1</scale>
          </mesh>
        </geometry>
        <surface>
          <friction>
            <ode>
              <mu>1</mu>
              <mu2>1</mu2>
              <fdir1>0 0 0</fdir1>
              <slip1>0</slip1>
              <slip2>0</slip2>
            </ode>
            <torsional>
              <coefficient>1</coefficient>
              <patch_radius>0</patch_radius>
              <surface_radius>0</surface_radius>
              <use_patch_radius>1</use_patch_radius>
              <ode>
                <slip>0</slip>
              </ode>
            </torsional>
          </friction>
          <bounce>
            <restitution_coefficient>0</restitution_coefficient>
            <threshold>1e+06</threshold>
          </bounce>
          <contact>
            <collide_without_contact>0</collide_without_contact>
            <collide_without_contact_bitmask>1</collide_without_contact_bitmask>
            <collide_bitmask>1</collide_bitmask>
            <ode>
              <soft_cfm>0</soft_cfm>
              <soft_erp>0.2</soft_erp>
              <kp>1e+13</kp>
              <kd>1</kd>
              <max_vel>0.01</max_vel>
              <min_depth>0</min_depth>
            </ode>
            <bullet>
              <split_impulse>1</split_impulse>
              <split_impulse_penetration_threshold>-0.01</split_impulse_penetration_threshold>
              <soft_cfm>0</soft_cfm>
              <soft_erp>0.2</soft_erp>
              <kp>1e+13</kp>
              <kd>1</kd>
            </bullet>
          </contact>
        </surface>
      </collision>
    </link>
    <link name='panda_link4'>
      <pose frame=''>0.0825 0 0.649 1.5708 -0 0</pose>
      <inertial>
        <pose frame=''>-0.036045 0.033685 0.031882 0 -0 0</pose>
        <mass>2.38</mass>
        <inertia>
          <ixx>0.00799664</ixx>
          <ixy>0.00347096</ixy>
          <ixz>-0.00241223</ixz>
          <iyy>0.00825391</iyy>
          <iyz>0.00235774</iyz>
          <izz>0.0102515</izz>
        </inertia>
      </inertial>
      <gravity>1</gravity>
      <velocity_decay/>
      <self_collide>0</self_collide>
      <enable_wind>0</enable_wind>
      <kinematic>0</kinematic>
      <visual name='panda_link4_visual'>
        <pose frame=''>0 0 0 0 -0 0</pose>
        <geometry>
          <mesh>
            <scale>1 1 1</scale>
            <uri>/home/medad/RoboticsProject/catkin_ws/src/franka_gazebo/meshes/visual/link4.dae</uri>
          </mesh>
        </geometry>
        <transparency>0</transparency>
        <cast_shadows>1</cast_shadows>
      </visual>
      <collision name='panda_link4_collision'>
        <laser_retro>0</laser_retro>
        <max_contacts>10</max_contacts>
        <pose frame=''>0 0 0 0 -0 0</pose>
        <geometry>
          <mesh>
            <uri>/home/medad/RoboticsProject/catkin_ws/src/franka_gazebo/meshes/collision/link4.stl</uri>
            <scale>1 1 1</scale>
          </mesh>
        </geometry>
        <surface>
          <friction>
            <ode>
              <mu>1</mu>
              <mu2>1</mu2>
              <fdir1>0 0 0</fdir1>
              <slip1>0</slip1>
              <slip2>0</slip2>
            </ode>
            <torsional>
              <coefficient>1</coefficient>
              <patch_radius>0</patch_radius>
              <surface_radius>0</surface_radius>
              <use_patch_radius>1</use_patch_radius>
              <ode>
                <slip>0</slip>
              </ode>
            </torsional>
          </friction>
          <bounce>
            <restitution_coefficient>0</restitution_coefficient>
            <threshold>1e+06</threshold>
          </bounce>
          <contact>
            <collide_without_contact>0</collide_without_contact>
            <collide_without_contact_bitmask>1</collide_without_contact_bitmask>
            <collide_bitmask>1</collide_bitmask>
            <ode>
              <soft_cfm>0</soft_cfm>
              <soft_erp>0.2</soft_erp>
              <kp>1e+13</kp>
              <kd>1</kd>
              <max_vel>0.01</max_vel>
              <min_depth>0</min_depth>
            </ode>
            <bullet>
              <split_impulse>1</split_impulse>
              <split_impulse_penetration_threshold>-0.01</split_impulse_penetration_threshold>
              <soft_cfm>0</soft_cfm>
              <soft_erp>0.2</soft_erp>
              <kp>1e+13</kp>
              <kd>1</kd>
            </bullet>
          </contact>
        </surface>
      </collision>
    </link>
    <link name='panda_link5'>
      <pose frame=''>0 0 1.033 0 -0 0</pose>
      <inertial>
        <pose frame=''>0 0.061043 -0.104176 0 -0 0</pose>
        <mass>2.74</mass>
        <inertia>
          <ixx>0.0303714</ixx>
          <ixy>6.5e-07</ixy>
          <ixz>0</ixz>
          <iyy>0.0288753</iyy>
          <iyz>0</iyz>
          <izz>0.00444134</izz>
        </inertia>
      </inertial>
      <gravity>1</gravity>
      <velocity_decay/>
      <self_collide>0</self_collide>
      <enable_wind>0</enable_wind>
      <kinematic>0</kinematic>
      <visual name='panda_link5_visual'>
        <pose frame=''>0 0 0 0 -0 0</pose>
        <geometry>
          <mesh>
            <scale>1 1 1</scale>
            <uri>/home/medad/RoboticsProject/catkin_ws/src/franka_gazebo/meshes/visual/link5.dae</uri>
          </mesh>
        </geometry>
        <transparency>0</transparency>
        <cast_shadows>1</cast_shadows>
        <material>
          <script>
            <name>Gazebo/Green</name>
          </script>
          <shader type='vertex'>
            <normal_map>__default__</normal_map>
          </shader>
          <ambient>0.5 1 0 1</ambient>
          <diffuse>0 1 0 1</diffuse>
          <specular>0.1 0.1 0.1 1</specular>
          <emissive>0 0 0 1</emissive>
        </material>
      </visual>
      <collision name='panda_link5_collision'>
        <laser_retro>0</laser_retro>
        <max_contacts>10</max_contacts>
        <pose frame=''>0 0 0 0 -0 0</pose>
        <geometry>
          <mesh>
            <uri>/home/medad/RoboticsProject/catkin_ws/src/franka_gazebo/meshes/collision/link5.stl</uri>
            <scale>1 1 1</scale>
          </mesh>
        </geometry>
        <surface>
          <friction>
            <ode>
              <mu>1</mu>
              <mu2>1</mu2>
              <fdir1>0 0 0</fdir1>
              <slip1>0</slip1>
              <slip2>0</slip2>
            </ode>
            <torsional>
              <coefficient>1</coefficient>
              <patch_radius>0</patch_radius>
              <surface_radius>0</surface_radius>
              <use_patch_radius>1</use_patch_radius>
              <ode>
                <slip>0</slip>
              </ode>
            </torsional>
          </friction>
          <bounce>
            <restitution_coefficient>0</restitution_coefficient>
            <threshold>1e+06</threshold>
          </bounce>
          <contact>
            <collide_without_contact>0</collide_without_contact>
            <collide_without_contact_bitmask>1</collide_without_contact_bitmask>
            <collide_bitmask>1</collide_bitmask>
            <ode>
              <soft_cfm>0</soft_cfm>
              <soft_erp>0.2</soft_erp>
              <kp>1e+13</kp>
              <kd>1</kd>
              <max_vel>0.01</max_vel>
              <min_depth>0</min_depth>
            </ode>
            <bullet>
              <split_impulse>1</split_impulse>
              <split_impulse_penetration_threshold>-0.01</split_impulse_penetration_threshold>
              <soft_cfm>0</soft_cfm>
              <soft_erp>0.2</soft_erp>
              <kp>1e+13</kp>
              <kd>1</kd>
            </bullet>
          </contact>
        </surface>
      </collision>
    </link>
    <link name='panda_link6'>
      <pose frame=''>0 0 1.033 1.5708 -0 0</pose>
      <inertial>
        <pose frame=''>0.051051 0.009108 0.010634 0 -0 0</pose>
        <mass>1.55</mass>
        <inertia>
          <ixx>0.00303336</ixx>
          <ixy>-0.000437277</ixy>
          <ixz>0.000629257</ixz>
          <iyy>0.0040448</iyy>
          <iyz>0.000130472</iyz>
          <izz>0.00558234</izz>
        </inertia>
      </inertial>
      <gravity>1</gravity>
      <velocity_decay/>
      <self_collide>0</self_collide>
      <enable_wind>0</enable_wind>
      <kinematic>0</kinematic>
      <visual name='panda_link6_visual'>
        <pose frame=''>0 0 0 0 -0 0</pose>
        <geometry>
          <mesh>
            <scale>1 1 1</scale>
            <uri>/home/medad/RoboticsProject/catkin_ws/src/franka_gazebo/meshes/visual/link6.dae</uri>
          </mesh>
        </geometry>
        <transparency>0</transparency>
        <cast_shadows>1</cast_shadows>
      </visual>
      <collision name='panda_link6_collision'>
        <laser_retro>0</laser_retro>
        <max_contacts>10</max_contacts>
        <pose frame=''>0 0 0 0 -0 0</pose>
        <geometry>
          <mesh>
            <uri>/home/medad/RoboticsProject/catkin_ws/src/franka_gazebo/meshes/collision/link6.stl</uri>
            <scale>1 1 1</scale>
          </mesh>
        </geometry>
        <surface>
          <friction>
            <ode>
              <mu>1</mu>
              <mu2>1</mu2>
              <fdir1>0 0 0</fdir1>
              <slip1>0</slip1>
              <slip2>0</slip2>
            </ode>
            <torsional>
              <coefficient>1</coefficient>
              <patch_radius>0</patch_radius>
              <surface_radius>0</surface_radius>
              <use_patch_radius>1</use_patch_radius>
              <ode>
                <slip>0</slip>
              </ode>
            </torsional>
          </friction>
          <bounce>
            <restitution_coefficient>0</restitution_coefficient>
            <threshold>1e+06</threshold>
          </bounce>
          <contact>
            <collide_without_contact>0</collide_without_contact>
            <collide_without_contact_bitmask>1</collide_without_contact_bitmask>
            <collide_bitmask>1</collide_bitmask>
            <ode>
              <soft_cfm>0</soft_cfm>
              <soft_erp>0.2</soft_erp>
              <kp>1e+13</kp>
              <kd>1</kd>
              <max_vel>0.01</max_vel>
              <min_depth>0</min_depth>
            </ode>
            <bullet>
              <split_impulse>1</split_impulse>
              <split_impulse_penetration_threshold>-0.01</split_impulse_penetration_threshold>
              <soft_cfm>0</soft_cfm>
              <soft_erp>0.2</soft_erp>
              <kp>1e+13</kp>
              <kd>1</kd>
            </bullet>
          </contact>
        </surface>
      </collision>
    </link>
    <link name='panda_link7'>
      <pose frame=''>0.088 0 1.033 3.14159 -0 0</pose>
      <inertial>
        <pose frame=''>0.005284 0.00521 0.105019 0 -0 0</pose>
        <mass>1.27</mass>
        <inertia>
          <ixx>0.00401245</ixx>
          <ixy>-0.00134501</ixy>
          <ixz>0.000253409</ixz>
          <iyy>0.00401263</iyy>
          <iyz>0.000116421</iyz>
          <izz>0.00334115</izz>
        </inertia>
      </inertial>
      <velocity_decay/>
      <velocity_decay/>
      <gravity>1</gravity>
      <velocity_decay/>
      <self_collide>0</self_collide>
      <enable_wind>0</enable_wind>
      <kinematic>0</kinematic>
      <visual name='panda_link7_visual'>
        <pose frame=''>0 0 0 0 -0 0</pose>
        <geometry>
          <mesh>
            <scale>1 1 1</scale>
            <uri>/home/medad/RoboticsProject/catkin_ws/src/franka_gazebo/meshes/visual/link7.dae</uri>
          </mesh>
        </geometry>
        <transparency>0</transparency>
        <cast_shadows>1</cast_shadows>
      </visual>
      <visual name='panda_link7_fixed_joint_lump__panda_hand_visual_1'>
        <pose frame=''>0 0 0.107 0 0 -0.785398</pose>
        <geometry>
          <mesh>
            <scale>1 1 1</scale>
            <uri>/home/medad/RoboticsProject/catkin_ws/src/franka_gazebo/meshes/visual/hand.dae</uri>
          </mesh>
        </geometry>
        <transparency>0</transparency>
        <cast_shadows>1</cast_shadows>
      </visual>
      <collision name='panda_link7_collision'>
        <laser_retro>0</laser_retro>
        <max_contacts>10</max_contacts>
        <pose frame=''>0 0 0 0 -0 0</pose>
        <geometry>
          <mesh>
            <uri>/home/medad/RoboticsProject/catkin_ws/src/franka_gazebo/meshes/collision/link7.stl</uri>
            <scale>1 1 1</scale>
          </mesh>
        </geometry>
        <surface>
          <friction>
            <ode>
              <mu>1</mu>
              <mu2>1</mu2>
              <fdir1>0 0 0</fdir1>
              <slip1>0</slip1>
              <slip2>0</slip2>
            </ode>
            <torsional>
              <coefficient>1</coefficient>
              <patch_radius>0</patch_radius>
              <surface_radius>0</surface_radius>
              <use_patch_radius>1</use_patch_radius>
              <ode>
                <slip>0</slip>
              </ode>
            </torsional>
          </friction>
          <bounce>
            <restitution_coefficient>0</restitution_coefficient>
            <threshold>1e+06</threshold>
          </bounce>
          <contact>
            <collide_without_contact>0</collide_without_contact>
            <collide_without_contact_bitmask>1</collide_without_contact_bitmask>
            <collide_bitmask>1</collide_bitmask>
            <ode>
              <soft_cfm>0</soft_cfm>
              <soft_erp>0.2</soft_erp>
              <kp>1e+13</kp>
              <kd>1</kd>
              <max_vel>0.01</max_vel>
              <min_depth>0</min_depth>
            </ode>
            <bullet>
              <split_impulse>1</split_impulse>
              <split_impulse_penetration_threshold>-0.01</split_impulse_penetration_threshold>
              <soft_cfm>0</soft_cfm>
              <soft_erp>0.2</soft_erp>
              <kp>1e+13</kp>
              <kd>1</kd>
            </bullet>
          </contact>
        </surface>
      </collision>
      <collision name='panda_link7_fixed_joint_lump__panda_hand_collision_1'>
        <laser_retro>0</laser_retro>
        <max_contacts>10</max_contacts>
        <pose frame=''>0 0 0.107 0 0 -0.785398</pose>
        <geometry>
          <mesh>
            <uri>/home/medad/RoboticsProject/catkin_ws/src/franka_gazebo/meshes/collision/hand.stl</uri>
            <scale>1 1 1</scale>
          </mesh>
        </geometry>
        <surface>
          <friction>
            <ode>
              <mu>1</mu>
              <mu2>1</mu2>
              <fdir1>0 0 0</fdir1>
              <slip1>0</slip1>
              <slip2>0</slip2>
            </ode>
            <torsional>
              <coefficient>1</coefficient>
              <patch_radius>0</patch_radius>
              <surface_radius>0</surface_radius>
              <use_patch_radius>1</use_patch_radius>
              <ode>
                <slip>0</slip>
              </ode>
            </torsional>
          </friction>
          <bounce>
            <restitution_coefficient>0</restitution_coefficient>
            <threshold>1e+06</threshold>
          </bounce>
          <contact>
            <collide_without_contact>0</collide_without_contact>
            <collide_without_contact_bitmask>1</collide_without_contact_bitmask>
            <collide_bitmask>1</collide_bitmask>
            <ode>
              <soft_cfm>0</soft_cfm>
              <soft_erp>0.2</soft_erp>
              <kp>1e+13</kp>
              <kd>1</kd>
              <max_vel>0.01</max_vel>
              <min_depth>0</min_depth>
            </ode>
            <bullet>
              <split_impulse>1</split_impulse>
              <split_impulse_penetration_threshold>-0.01</split_impulse_penetration_threshold>
              <soft_cfm>0</soft_cfm>
              <soft_erp>0.2</soft_erp>
              <kp>1e+13</kp>
              <kd>1</kd>
            </bullet>
          </contact>
        </surface>
      </collision>
    </link>
    <link name='panda_rightfinger'>
      <pose frame=''>0.088 -0 0.8676 3.14159 -0 0.785398</pose>
      <inertial>
        <pose frame=''>0 0.014564 0.022794 0 -0 -3.14159</pose>
        <mass>0.1</mass>
        <inertia>
          <ixx>3.01221e-05</ixx>
          <ixy>0</ixy>
          <ixz>0</ixz>
          <iyy>2.95874e-05</iyy>
          <iyz>0</iyz>
          <izz>6.95125e-06</izz>
        </inertia>
      </inertial>
      <velocity_decay/>
      <gravity>1</gravity>
      <velocity_decay/>
      <self_collide>0</self_collide>
      <enable_wind>0</enable_wind>
      <kinematic>0</kinematic>
      <visual name='panda_rightfinger_visual'>
        <pose frame=''>0 0 0 0 -0 -3.14159</pose>
        <geometry>
          <mesh>
            <scale>1 1 1</scale>
            <uri>/home/medad/RoboticsProject/catkin_ws/src/franka_gazebo/meshes/visual/finger.dae</uri>
          </mesh>
        </geometry>
        <material>
          <script>
            <uri>__default__</uri>
            <name>__default__</name>
          </script>
        </material>
        <transparency>0</transparency>
        <cast_shadows>1</cast_shadows>
      </visual>
      <collision name='panda_rightfinger_collision'>
        <laser_retro>0</laser_retro>
        <max_contacts>10</max_contacts>
        <pose frame=''>0 0 0 0 0 -3.14159</pose>
        <geometry>
          <mesh>
            <uri>/home/medad/RoboticsProject/catkin_ws/src/franka_gazebo/meshes/collision/finger.stl</uri>
            <scale>1 1 1</scale>
          </mesh>
        </geometry>
        <surface>
          <friction>
            <ode>
              <mu>100</mu>
              <mu2>100</mu2>
              <fdir1>0 0 1</fdir1>
              <slip1>0</slip1>
              <slip2>0</slip2>
            </ode>
            <torsional>
              <coefficient>100</coefficient>
              <patch_radius>0.1</patch_radius>
              <surface_radius>0.1</surface_radius>
              <use_patch_radius>1</use_patch_radius>
              <ode>
                <slip>0</slip>
              </ode>
            </torsional>
          </friction>
          <bounce>
            <restitution_coefficient>0</restitution_coefficient>
            <threshold>1e+06</threshold>
          </bounce>
          <contact>
            <collide_without_contact>0</collide_without_contact>
            <collide_without_contact_bitmask>1</collide_without_contact_bitmask>
            <collide_bitmask>1</collide_bitmask>
            <ode>
              <soft_cfm>0</soft_cfm>
              <soft_erp>0.2</soft_erp>
              <kp>100000</kp>
              <kd>1</kd>
              <max_vel>0.01</max_vel>
              <min_depth>0</min_depth>
            </ode>
            <bullet>
              <split_impulse>1</split_impulse>
              <split_impulse_penetration_threshold>-0.01</split_impulse_penetration_threshold>
              <soft_cfm>0</soft_cfm>
              <soft_erp>0.2</soft_erp>
              <kp>100000</kp>
              <kd>1</kd>
            </bullet>
          </contact>
        </surface>
      </collision>
    </link>
    <joint name='panda_finger_joint1' type='prismatic'>
      <parent>panda_link7</parent>
      <child>panda_leftfinger</child>
      <pose frame=''>0 0 0 0 -0 0</pose>
      <axis>
        <xyz>0.707107 -0.707107 0</xyz>
        <use_parent_model_frame>1</use_parent_model_frame>
        <limit>
          <lower>-0.001</lower>
          <upper>0.06</upper>
          <effort>50</effort>
          <velocity>0.1</velocity>
        </limit>
        <dynamics>
          <spring_reference>0</spring_reference>
          <spring_stiffness>0</spring_stiffness>
          <damping>0</damping>
          <friction>0</friction>
        </dynamics>
      </axis>
      <physics>
        <ode>
          <limit>
            <cfm>0</cfm>
            <erp>0.2</erp>
          </limit>
          <suspension>
            <cfm>0</cfm>
            <erp>0.2</erp>
          </suspension>
        </ode>
      </physics>
    </joint>
    <joint name='panda_finger_joint2' type='prismatic'>
      <parent>panda_link7</parent>
      <child>panda_rightfinger</child>
      <pose frame=''>0 0 0 0 -0 0</pose>
      <axis>
        <xyz>-0.707107 0.707107 -0</xyz>
        <use_parent_model_frame>1</use_parent_model_frame>
        <limit>
          <lower>-0.001</lower>
          <upper>0.06</upper>
          <effort>50</effort>
          <velocity>0.1</velocity>
        </limit>
        <dynamics>
          <spring_reference>0</spring_reference>
          <spring_stiffness>0</spring_stiffness>
          <damping>0</damping>
          <friction>0</friction>
        </dynamics>
      </axis>
      <physics>
        <ode>
          <limit>
            <cfm>0</cfm>
            <erp>0.2</erp>
          </limit>
          <suspension>
            <cfm>0</cfm>
            <erp>0.2</erp>
          </suspension>
        </ode>
      </physics>
    </joint>
    <joint name='panda_joint1' type='revolute'>
      <parent>panda_link0</parent>
      <child>panda_link1</child>
      <pose frame=''>0 0 0 0 -0 0</pose>
      <axis>
        <xyz>0 0 1</xyz>
        <use_parent_model_frame>1</use_parent_model_frame>
        <limit>
          <lower>-2.8973</lower>
          <upper>2.8973</upper>
          <effort>87</effort>
          <velocity>2.175</velocity>
        </limit>
        <dynamics>
          <spring_reference>0</spring_reference>
          <spring_stiffness>0</spring_stiffness>
          <damping>0</damping>
          <friction>0</friction>
        </dynamics>
      </axis>
      <physics>
        <ode>
          <limit>
            <cfm>0</cfm>
            <erp>0.2</erp>
          </limit>
          <suspension>
            <cfm>0</cfm>
            <erp>0.2</erp>
          </suspension>
        </ode>
      </physics>
    </joint>
    <joint name='panda_joint2' type='revolute'>
      <parent>panda_link1</parent>
      <child>panda_link2</child>
      <pose frame=''>0 0 0 0 -0 0</pose>
      <axis>
        <xyz>0 1 0</xyz>
        <use_parent_model_frame>1</use_parent_model_frame>
        <limit>
          <lower>-1.7628</lower>
          <upper>1.7628</upper>
          <effort>87</effort>
          <velocity>2.175</velocity>
        </limit>
        <dynamics>
          <spring_reference>0</spring_reference>
          <spring_stiffness>0</spring_stiffness>
          <damping>0</damping>
          <friction>0</friction>
        </dynamics>
      </axis>
      <physics>
        <ode>
          <limit>
            <cfm>0</cfm>
            <erp>0.2</erp>
          </limit>
          <suspension>
            <cfm>0</cfm>
            <erp>0.2</erp>
          </suspension>
        </ode>
      </physics>
    </joint>
    <joint name='panda_joint3' type='revolute'>
      <parent>panda_link2</parent>
      <child>panda_link3</child>
      <pose frame=''>0 0 0 0 -0 0</pose>
      <axis>
        <xyz>0 0 1</xyz>
        <use_parent_model_frame>1</use_parent_model_frame>
        <limit>
          <lower>-2.8973</lower>
          <upper>2.8973</upper>
          <effort>87</effort>
          <velocity>2.175</velocity>
        </limit>
        <dynamics>
          <spring_reference>0</spring_reference>
          <spring_stiffness>0</spring_stiffness>
          <damping>0</damping>
          <friction>0</friction>
        </dynamics>
      </axis>
      <physics>
        <ode>
          <limit>
            <cfm>0</cfm>
            <erp>0.2</erp>
          </limit>
          <suspension>
            <cfm>0</cfm>
            <erp>0.2</erp>
          </suspension>
        </ode>
      </physics>
    </joint>
    <joint name='panda_joint4' type='revolute'>
      <parent>panda_link3</parent>
      <child>panda_link4</child>
      <pose frame=''>0 0 0 0 -0 0</pose>
      <axis>
        <xyz>0 -1 0</xyz>
        <use_parent_model_frame>1</use_parent_model_frame>
        <limit>
          <lower>-3.0718</lower>
          <upper>0.0698</upper>
          <effort>87</effort>
          <velocity>2.175</velocity>
        </limit>
        <dynamics>
          <spring_reference>0</spring_reference>
          <spring_stiffness>0</spring_stiffness>
          <damping>0</damping>
          <friction>0</friction>
        </dynamics>
      </axis>
      <physics>
        <ode>
          <limit>
            <cfm>0</cfm>
            <erp>0.2</erp>
          </limit>
          <suspension>
            <cfm>0</cfm>
            <erp>0.2</erp>
          </suspension>
        </ode>
      </physics>
    </joint>
    <joint name='panda_joint5' type='revolute'>
      <parent>panda_link4</parent>
      <child>panda_link5</child>
      <pose frame=''>0 0 0 0 -0 0</pose>
      <axis>
        <xyz>0 0 1</xyz>
        <use_parent_model_frame>1</use_parent_model_frame>
        <limit>
          <lower>-2.8973</lower>
          <upper>2.8973</upper>
          <effort>12</effort>
          <velocity>2.61</velocity>
        </limit>
        <dynamics>
          <spring_reference>0</spring_reference>
          <spring_stiffness>0</spring_stiffness>
          <damping>0</damping>
          <friction>0</friction>
        </dynamics>
      </axis>
      <physics>
        <ode>
          <limit>
            <cfm>0</cfm>
            <erp>0.2</erp>
          </limit>
          <suspension>
            <cfm>0</cfm>
            <erp>0.2</erp>
          </suspension>
        </ode>
      </physics>
    </joint>
    <joint name='panda_joint6' type='revolute'>
      <parent>panda_link5</parent>
      <child>panda_link6</child>
      <pose frame=''>0 0 0 0 -0 0</pose>
      <axis>
        <xyz>0 -1 0</xyz>
        <use_parent_model_frame>1</use_parent_model_frame>
        <limit>
          <lower>-0.0175</lower>
          <upper>3.7525</upper>
          <effort>12</effort>
          <velocity>2.61</velocity>
        </limit>
        <dynamics>
          <spring_reference>0</spring_reference>
          <spring_stiffness>0</spring_stiffness>
          <damping>0</damping>
          <friction>0</friction>
        </dynamics>
      </axis>
      <physics>
        <ode>
          <limit>
            <cfm>0</cfm>
            <erp>0.2</erp>
          </limit>
          <suspension>
            <cfm>0</cfm>
            <erp>0.2</erp>
          </suspension>
        </ode>
      </physics>
    </joint>
    <joint name='panda_joint7' type='revolute'>
      <parent>panda_link6</parent>
      <child>panda_link7</child>
      <pose frame=''>0 0 0 0 -0 0</pose>
      <axis>
        <xyz>0 -0 -1</xyz>
        <use_parent_model_frame>1</use_parent_model_frame>
        <limit>
          <lower>-2.8973</lower>
          <upper>2.8973</upper>
          <effort>12</effort>
          <velocity>2.61</velocity>
        </limit>
        <dynamics>
          <spring_reference>0</spring_reference>
          <spring_stiffness>0</spring_stiffness>
          <damping>0</damping>
          <friction>0</friction>
        </dynamics>
      </axis>
      <physics>
        <ode>
          <limit>
            <cfm>0</cfm>
            <erp>0.2</erp>
          </limit>
          <suspension>
            <cfm>0</cfm>
            <erp>0.2</erp>
          </suspension>
        </ode>
      </physics>
    </joint>
    <static>0</static>
    <allow_auto_disable>1</allow_auto_disable>
    <plugin name='gazebo_ros_control' filename='libgazebo_ros_control.so'>
      <robotNamespace>/</robotNamespace>
    </plugin>
  </model>
</sdf>
